Workbook
Name PROV_AIR_E_S_A_S__E_S_P_: LISTAS!$B$3:$B$3
Name PROV_ASTURIAS_SOLUCIONES_DE_INGENIERIA_BUCEO_COMERCIAL_Y_DRAGADO_SAS: LISTAS!$C$3:$C$4
Name PROV_CASALIMPIA_SA: LISTAS!$D$3:$D$4
Name PROV_CLARO_S_A_: LISTAS!$E$3:$E$10
Name PROV_COMPANIA_PAPELERA_NACIONAL_S_A_S: LISTAS!$F$3:$F$4
Name PROV_COMPUASOCIADOS: LISTAS!$G$3:$G$3
Name PROV_CONTRATOS_Y_FIANZAS_DE_ARRENDAMIENTO_S_A_S_: LISTAS!$H$3:$H$3
Name PROV_COORSERPARK: LISTAS!$I$3:$I$3
Name PROV_EDIFICIO_CAPITAL_TOWERS_PROPIEDAD_HORIZONTAL: LISTAS!$J$3:$J$5
Name PROV_EDIFICIO_PORTUS_MANGA_CARTAGENA: LISTAS!$K$3:$K$5
Name PROV_EDIFICIO_TORRES_DEL_ATLANTICO: LISTAS!$L$3:$L$3
Name PROV_EMERMEDICA_S_A_: LISTAS!$M$3:$M$4
Name PROV_EMPRESAS_MUNICIPALES_DE_CALI: LISTAS!$N$3:$N$3
Name PROV_EMPRESAS_PUBLICAS_DE_MEDELLIN_E_S_P: LISTAS!$O$3:$O$3
Name PROV_ETB_S_A__E_S_P: LISTAS!$P$3:$P$3
Name PROV_FEDERACION_COLOMBIANA_AGENTES_LOGISTICOS: LISTAS!$Q$3:$Q$5
Name PROV_FUNDACION_UN_TECHO_PARA_MI_PAIS_COLOMBIA: LISTAS!$R$3:$R$3
Name PROV_HARDSOFT_SOLUTIONS_INTEGRAL_SAS: LISTAS!$S$3:$S$3
Name PROV_IFX_NETWORKS_COLOMBIA_S_A_S_: LISTAS!$T$3:$T$4
Name PROV_INTERASEO_AEROPUERTO: LISTAS!$U$3:$U$3
Name PROV_INVERSIONES_HOTELERAS_BUENAVENTURA_S_A_S_: LISTAS!$V$3:$V$3
Name PROV_JAVIER_ANTONIO_SANCHEZ_O_: LISTAS!$W$3:$W$3
Name PROV_JCO_INVERSIONES_S_A_S: LISTAS!$X$3:$X$3
Name PROV_KEY_WAY_BUSINESS_CONSULTING_SAS: LISTAS!$Y$3:$Y$3
Name PROV_LI_STORAGE_SAS: LISTAS!$Z$3:$Z$3
Name PROV_LUZ_DARY_MINA_GARCES: LISTAS!$AA$3:$AA$3
Name PROV_MARVAL_S_A_S_: LISTAS!$AB$3:$AB$3
Name PROV_MEDISANITAS_S_A_S_: LISTAS!$AC$3:$AC$3
Name PROV_MOVISTAR: LISTAS!$AD$3:$AD$5
Name PROV_MULTICOPY_JV_ZOMAC_SAS: LISTAS!$AE$3:$AE$3
Name PROV_OPAIN_SA_AEROPUERTO_EL_DORADO: LISTAS!$AF$3:$AF$3
Name PROV_PALAN_SOCIEDAD_POR_ACCIONES_SIMPLIFICADA: LISTAS!$AG$3:$AG$3
Name PROV_PATRIMONIOS_AUTONOMOS_FIDUCIARIA_BANCOLOMBIA_S_A: LISTAS!$AH$3:$AH$4
Name PROV_PORTUS_GLOBAL_SAS: LISTAS!$AI$3:$AI$3
Name PROV_PRUEBA: LISTAS!$AQ$3:$AQ$4
Name PROV_SERVIDOMESTICAS_SAS: LISTAS!$AJ$3:$AJ$3
Name PROV_SUMAR_INVERSIONES_Y_PROYECTOS_S_A_S_: LISTAS!$AK$3:$AK$3
Name PROV_TECNOLOGIA_INFORMATICA_TECINF_SAS: LISTAS!$AL$3:$AL$3
Name PROV_TRAIKER_GROUP_COLOMBIA_S_A_S_: LISTAS!$AM$3:$AM$3
Name PROV_TRANS_INTERNATIONAL_COURIER_S_A_S: LISTAS!$AN$3:$AN$3
Name PROV_TRIPLE_A: LISTAS!$AO$3:$AO$3
Name PROV_UNE_EPM_TELECOMUNICACIONES_S_A: LISTAS!$AP$3:$AP$5
Name PROVEEDORES: LISTAS!$A$3:$A$44

Sheet MAESTRA
A1: BASE MAESTRA DE HOMOLOGACIÓN — CRAFT | No editar directamente
A2: CLAVE (no editar) | B2: NIT | C2: PROVEEDOR | D2: SERVICIO | E2: ÁREA | F2: P&L | G2: CUENTA CONTABLE | H2: GLOSA ESTÁNDAR | I2: TIPO | J2: SUCURSAL
A3: EDIFICIO CAPITAL TOWERS PROPIEDAD HORIZONTAL|||Arriendo bodega | B3: 830082820-5 | C3: EDIFICIO CAPITAL TOWERS PROPIEDAD HORIZONTAL | D3: Arriendo bodega | E3: ADM | F3: CONSTRUCCIONES Y EDIFICACIONES | G3: CONSTRUCCIONES Y EDIFICACIONES | H3: ARRIENDO BODEGA OF BOG | I3: Fijo | J3: Calle 100
A4: EDIFICIO CAPITAL TOWERS PROPIEDAD HORIZONTAL|||Administración oficina | B4: 830082820-5 | C4: EDIFICIO CAPITAL TOWERS PROPIEDAD HORIZONTAL | D4: Administración oficina | E4: ADM | F4: CONSTRUCCIONES Y EDIFICACIONES | G4: ADMINISTRACIÓN OFICINA | H4: /SERV ADMINISTRACIÓN OF/ BOG | I4: Fijo | J4: Calle 100
A5: EDIFICIO CAPITAL TOWERS PROPIEDAD HORIZONTAL|||Servicios públicos | B5: 830082820-5 | C5: EDIFICIO CAPITAL TOWERS PROPIEDAD HORIZONTAL | D5: Servicios públicos | E5: ADM | F5: ENERGIA ELECTRICA - ACUEDUCTO Y ALCANTARILLADO | G5: ENERGIA ELECTRICA - ACUEDUCTO Y ALCANTARILLADO | H5: SERVICIOS PUBLICOS OF BOG | I5: Fijo | J5: Calle 100
A6: PALAN SOCIEDAD POR ACCIONES SIMPLIFICADA|||Canon arriendo oficina | B6: 830111934-1 | C6: PALAN SOCIEDAD POR ACCIONES SIMPLIFICADA | D6: Canon arriendo oficina | E6: ADM | F6: CONSTRUCCIONES Y EDIFICACIONES | G6: CONSTRUCCIONES Y EDIFICACIONES | H6: CANON ARRIENDO OF BOG | I6: Fijo | J6: Calle 100
A7: PATRIMONIOS AUTONOMOS FIDUCIARIA BANCOLOMBIA S A|||Canon arriendo aeropuerto | B7: 830054539-0 | C7: PATRIMONIOS AUTONOMOS FIDUCIARIA BANCOLOMBIA S A | D7: Canon arriendo aeropuerto | E7: ADM | F7: CONSTRUCCIONES Y EDIFICACIONES | G7: CONSTRUCCIONES Y EDIFICACIONES | H7: CANON ARRIENDO OF AERPTO | I7: Fijo | J7: Aeropuerto
A8: PATRIMONIOS AUTONOMOS FIDUCIARIA BANCOLOMBIA S A|||Servicios públicos aeropuerto | B8: 830054539-0 | C8: PATRIMONIOS AUTONOMOS FIDUCIARIA BANCOLOMBIA S A | D8: Servicios públicos aeropuerto | E8: ADM | F8: ENERGIA ELECTRICA | G8: ENERGIA ELECTRICA | H8: SERVICIOS PUBLICOS OF AERPTO | I8: Fijo | J8: Aeropuerto
A9: LI STORAGE SAS|||Arriendo bodega externa | B9: 900705369-3 | C9: LI STORAGE SAS | D9: Arriendo bodega externa | E9: ADM | F9: CONSTRUCCIONES Y EDIFICACIONES | G9: CONSTRUCCIONES Y EDIFICACIONES | H9: ARRIENDO BODEGA EXTERNA OF BOG | I9: Fijo | J9: Calle 100
A10: ASTURIAS SOLUCIONES DE INGENIERIA BUCEO COMERCIAL Y DRAGADO SAS|||Canon arriendo oficina BUN | B10: 900081790-1 | C10: ASTURIAS SOLUCIONES DE INGENIERIA BUCEO COMERCIAL Y DRAGADO SAS | D10: Canon arriendo oficina BUN | E10: ADM | F10: CONSTRUCCIONES Y EDIFICACIONES | G10: CONSTRUCCIONES Y EDIFICACIONES | H10: CANON ARRIENDO OF BUN | I10: Fijo | J10: Buenaventura
A11: ASTURIAS SOLUCIONES DE INGENIERIA BUCEO COMERCIAL Y DRAGADO SAS|||Administración oficina BUN | B11: 900081790-1 | C11: ASTURIAS SOLUCIONES DE INGENIERIA BUCEO COMERCIAL Y DRAGADO SAS | D11: Administración oficina BUN | E11: ADM | F11: CONSTRUCCIONES Y EDIFICACIONES | G11: ADMINISTRACIÓN OFICINA | H11: /SERV ADMINISTRACIÓN OFC/ BUN | I11: Fijo | J11: Buenaventura
A12: JAVIER ANTONIO SANCHEZ O.|||Arriendo bodega BUN | B12: 1111750598-3 | C12: JAVIER ANTONIO SANCHEZ O. | D12: Arriendo bodega BUN | E12: ADM | F12: CONSTRUCCIONES Y EDIFICACIONES | G12: CONSTRUCCIONES Y EDIFICACIONES | H12: ARRIENDO BODEGA OF BUN | I12: Fijo | J12: Buenaventura
A13: PORTUS GLOBAL SAS|||Canon arriendo oficina CTG | B13: 900918697-9 | C13: PORTUS GLOBAL SAS | D13: Canon arriendo oficina CTG | E13: ADM | F13: CONSTRUCCIONES Y EDIFICACIONES | G13: CONSTRUCCIONES Y EDIFICACIONES | H13: CANON ARRIENDO OF CTG | I13: Fijo | J13: Cartagena
... A68: PRUEBA|||SERV2 | B68: 002 | C68: PRUEBA | D68: SERV2 | E68: adm | F68: cuota | G68: cuota | H68: cuota | I68: cuota | J68: cuota

Sheet LISTAS
A1: Hoja técnica — rangos para listas desplegables encadenadas
A2: PROVEEDORES | B2: AIR-E S.A.S. E.S.P. | C2: ASTURIAS SOLUCIONES DE INGENIERIA BUCEO COMERCIAL Y DRAGADO SAS | D2: CASALIMPIA SA | E2: CLARO S.A. | F2: COMPAÑIA PAPELERA NACIONAL S.A.S | G2: COMPUASOCIADOS | H2: CONTRATOS Y FIANZAS DE ARRENDAMIENTO S.A.S. | I2: COORSERPARK | J2: EDIFICIO CAPITAL TOWERS PROPIEDAD HORIZONTAL | K2: EDIFICIO PORTUS MANGA CARTAGENA | L2: EDIFICIO TORRES DEL ATLANTICO | M2: EMERMEDICA S.A. | N2: EMPRESAS MUNICIPALES DE CALI | O2: EMPRESAS PÚBLICAS DE MEDELLÍN E.S.P | P2: ETB S.A. E.S.P | Q2: FEDERACION COLOMBIANA AGENTES LOGISTICOS | R2: FUNDACION UN TECHO PARA MI PAIS COLOMBIA | S2: HARDSOFT SOLUTIONS INTEGRAL SAS | T2: IFX NETWORKS COLOMBIA S.A.S. | U2: INTERASEO AEROPUERTO | V2: INVERSIONES HOTELERAS BUENAVENTURA S.A.S. | W2: JAVIER ANTONIO SANCHEZ O. | X2: JCO INVERSIONES S.A.S | Y2: KEY WAY BUSINESS CONSULTING SAS | Z2: LI STORAGE SAS | AA2: LUZ DARY MINA GARCES | AB2: MARVAL S.A.S. | AC2: MEDISANITAS S.A.S. | AD2: MOVISTAR | AE2: MULTICOPY JV ZOMAC SAS | AF2: OPAIN SA AEROPUERTO EL DORADO | AG2: PALAN SOCIEDAD POR ACCIONES SIMPLIFICADA | AH2: PATRIMONIOS AUTONOMOS FIDUCIARIA BANCOLOMBIA S A | AI2: PORTUS GLOBAL SAS | AJ2: SERVIDOMESTICAS SAS | AK2: SUMAR INVERSIONES Y PROYECTOS S.A.S. | AL2: TECNOLOGIA INFORMATICA TECINF SAS | AM2: TRAIKER GROUP COLOMBIA S.A.S. | AN2: TRANS INTERNATIONAL COURIER S.A.S | AO2: TRIPLE A | AP2: UNE EPM TELECOMUNICACIONES S-A | AQ2: PRUEBA
A3: AIR-E S.A.S. E.S.P. | B3: Energía BRQ | C3: Canon arriendo oficina BUN | D3: Aseo oficina CTG | E3: SIM tablet BUN y aeropuerto | F3: Aseo y cafetería | G3: Soporte IT BUN | H3: Canon arriendo oficina MED | I3: Plan exequial colaboradores | J3: Arriendo bodega | K3: Administración oficina CTG | L3: Administración oficina BRQ | M3: Plan preferencial | N3: Servicios públicos CALI | O3: Servicios públicos MED | P3: Teléfono fijo BOG | Q3: Cuota FITAC BOG | R3: Donación fundación techo | S3: Soporte IT CTG | T3: SD WAN | U3: Recolección basura AERPTO | V3: Servicios públicos BUN | W3: Arriendo bodega BUN | X3: Parqueadero BOG | Y3: Sistema nómina y SS | Z3: Arriendo bodega externa | AA3: Aseo oficina BUN | AB3: Canon arriendo oficina BRQ | AC3: Medicina prepagada | AD3: Datos celulares BOG | AE3: Arriendo fotocopiadora BUN | AF3: Gastos reembolsables aeropuerto | AG3: Canon arriendo oficina | AH3: Canon arriendo aeropuerto | AI3: Canon arriendo oficina CTG | AJ3: Aseo oficina MED | AK3: Canon arriendo oficina CALI | AL3: Soporte VeamBackup | AM3: Arriendo bodega CTG | AN3: Mensajería nacional | AO3: Acueducto BRQ | AP3: Internet MED | AQ3: SERV1
A4: ASTURIAS SOLUCIONES DE INGENIERIA BUCEO COMERCIAL Y DRAGADO SAS | C4: Administración oficina BUN | D4: Aseo oficina CALI | E4: SIM tablet CTG | F4: Papelería | J4: Administración oficina | K4: Servicios públicos CTG | M4: Áreas protegidas | Q4: Cuota FITAC CTG | T4: Internet todas las sucursales | AD4: Datos celulares CTG | AH4: Servicios públicos aeropuerto | AP4: Teléfono fijo MED | AQ4: SERV2
A5: CASALIMPIA SA | E5: Datos móviles BOG | J5: Servicios públicos | K5: Parqueadero CTG | Q5: Cuota FITAC BUN | AD5: Datos celulares BUN | AP5: Número único MED
A6: CLARO S.A. | E6: Internet oficinas CTG y BUN
A7: COMPAÑIA PAPELERA NACIONAL S.A.S | E7: Internet oficinas BRQ
A8: COMPUASOCIADOS | E8: Internet y telefonía CALI
A9: CONTRATOS Y FIANZAS DE ARRENDAMIENTO S.A.S. | E9: Telefonía fija BUN y CTG
A10: COORSERPARK | E10: Celulares colaboradores
A11: EDIFICIO CAPITAL TOWERS PROPIEDAD HORIZONTAL
A12: EDIFICIO PORTUS MANGA CARTAGENA
A13: EDIFICIO TORRES DEL ATLANTICO
A14: EMERMEDICA S.A.
A15: EMPRESAS MUNICIPALES DE CALI
A16: EMPRESAS PÚBLICAS DE MEDELLÍN E.S.P
A17: ETB S.A. E.S.P
A18: FEDERACION COLOMBIANA AGENTES LOGISTICOS
A19: FUNDACION UN TECHO PARA MI PAIS COLOMBIA
A20: HARDSOFT SOLUTIONS INTEGRAL SAS
A21: IFX NETWORKS COLOMBIA S.A.S.
A22: INTERASEO AEROPUERTO
... A44: PRUEBA

Sheet REGISTRO
A1: REGISTRO DE FACTURAS — CRAFT | Paso 1: elige PROVEEDOR → Paso 2: elige SERVICIO → completa los campos amarillos
A2: 🟨 Campos amarillos = ingreso manual | 🟩 Campos verdes = automáticos (no editar) | El SERVICIO depende del PROVEEDOR elegido
A3: N° | B3: PROVEEDOR | C3: SERVICIO | D3: ÁREA | E3: P&L | F3: CUENTA CONTABLE | G3: GLOSA | H3: TIPO | I3: DETALLE DEL GASTO | J3: SUCURSAL | K3: N° FACTURA | L3: FECHA INGRESO | M3: FECHA REALIZACIÓN | N3: FECHA VENCIMIENTO | O3: MONTO FACTURA | P3: IVA | Q3: RETENCIÓN | R3: GASTO NETO | S3: MES EJECUCIÓN | T3: CDC | U3: FECHA PROCESADO FINANCIERO | V3: FECHA DE PAGO | W3: SOLICITANTE | X3: OBSERVACIONES | Y3: APROBACIÓN GERENCIA ADMINISTRATIVA | Z3: FECHA DE APROBACIÓN
A4: 1 | B4: JOSE JOAQIN ALARCON | I4: LAVAR CORINAS OF 802 CRAFT BOGOTA | K4: 23 | L4: 45672 | M4: 45672 | N4: 45674 | O4: 950000 | P4: 0 | Q4: 0 | R4: 950000 | S4: enero 2025 | T4: 3127 | X4: aprobado por correo | Y4: Aprobado
A5: 2 | B5: COMPAÑIA PAPELERA NACIONAL S.A.S | I5: PEDIDO ASEO CAFETERIA Y PAPELERIA SUC CRAFT MEDELLIN | K5: CPFP159410 | L5: 45672 | M5: 45672 | N5: 45702 | O5: 460019 | P5: 0 | Q5: 0 | R5: 460019 | S5: enero 2025 | T5: 41 | Y5: Aprobado
A6: 3 | B6: CASALIMPIA SA | D6: ADM | F6: Otros Gastos CASA LIMPIA PLANILLA AC OTROS | I6: SERVICIO DE ASEO GENERAL OFICINA CRAFT CARTAGENA | J6: Cartagena | K6: 1715986 | L6: 45672 | M6: 45672 | N6: 45702 | O6: 1695582 | P6: 0 | Q6: 0 | R6: 1695582 | S6: enero 2025 | T6: 15 | Y6: Aprobado
A7: 4 | B7: JAVIER ANTONIO SANCHEZ | I7: ARRIENDO CUARTO DE BODEGA CRAFT BUENAVENTURA | K7: 2025-01 | L7: 45672 | M7: 45672 | N7: 45681 | O7: 250000 | P7: 0 | Q7: 0 | R7: 250000 | S7: enero 2025 | T7: 13 | X7: aprobado por correo | Y7: Aprobado
A8: 5 | B8: MOVISTAR | I8: SERVICIO LINEAS CELULARES CRAFT BOGOTA | K8: BEC428170024 | L8: 45672 | M8: 45674 | N8: 45678 | O8: 1654002 | P8: 0 | Q8: 0 | R8: 1654002 | S8: enero 2025 | T8: 3587 | Y8: Aprobado
A9: 6 | B9: Controles Empresariales SAS | I9: RENOVACION DE SOPORTE DEL SERVIDOR | K9: FEI0000083306 | L9: 45674 | M9: 45674 | N9: 45674 | O9: 17314732 | P9: 0 | Q9: 0 | R9: 17314732 | S9: enero 2025 | T9: 4062 | Y9: Aprobado
A10: 7 | B10: COMPAÑIA PAPELERA NACIONAL S.A.S | I10: PEDIDO PAPELERIA CRAFT BOGOTA | K10: CPFP159834 | L10: 45674 | M10: 45674 | N10: 45704 | O10: 131711 | P10: 0 | Q10: 0 | R10: 131711 | S10: enero 2025 | T10: 3724 | Y10: Aprobado
A11: 8 | B11: FUNDACION UN TECHO PARA MI PAIS COLOMBIA | I11: DONACION CON TRABAJOS ASOCIADOS CON LA RAZON SOCIAL | K11: FS74 | L11: 45674 | M11: 45674 | N11: 45674 | O11: 100000 | P11: 0 | Q11: 0 | R11: 100000 | S11: enero 2025 | T11: 3728 | Y11: Aprobado
A12: 9 | B12: PC QUICK SAS | I12: 3 PORTATIL PARA GRACE FONSECA, PAULA RODRIGUEZ, NICOLAS SALDAÑA | K12: PFE8206 | L12: 45673 | M12: 45674 | N12: 45703 | O12: 7321320 | P12: 0 | Q12: 0 | R12: 7321320 | S12: enero 2025 | T12: 3740 | Y12: Aprobado
A13: 10 | B13: CHATOBRAND SAS | I13: SELLO FECHADOR PARA CRAFT BUN // IMPRESION VINILOS ADHESIVOS | K13: FEV207 | L13: 45672 | M13: 45674 | N13: 45681 | O13: 232050 | P13: 0 | Q13: 0 | R13: 232050 | S13: enero 2025 | T13: 3773 | Y13: Aprobado
A14: 11 | B14: OPAIN SA AEROPUERTO EL DORADO | I14: GASTOS REEMBOLSABLES CRAFT AEROPUERTO | K14: CCG-18598 | L14: 45672 | M14: 45674 | N14: 45681 | O14: 568140 | P14: 0 | Q14: 0 | R14: 568140 | S14: enero 2025 | T14: 4 | X14: aprobado por correo | Y14: Aprobado
A15: 12 | B15: CLARO S.A. | I15: SIM TABLET BUN Y AEROPUERTO | K15: E5895019052 | L15: 45676 | M15: 45677 | O15: 295057 | P15: 0 | Q15: 0 | R15: 295057 | S15: enero 2025 | T15: 18 | Y15: Aprobado
A16: 13 | B16: CLARO S.A. | I16: SIM TABLET CTG | K16: E5894996021 | L16: 45676 | M16: 45677 | O16: 174625 | P16: 0 | Q16: 0 | R16: 174625 | S16: enero 2025 | T16: 17 | Y16: Aprobado
A17: 14 | B17: COMPAÑIA ANDINA DE SEGURIDAD PRIVADA BIC LTDA. - ANDISEG BIC LTDA | I17: VISITAS DE SEGURIDAD ASOCIADOS DE NEGOCIO | K17: ANDI20822. | L17: 45677 | M17: 45678 | N17: 45707 | O17: 618800 | P17: 0 | Q17: 0 | R17: 618800 | S17: enero 2025 | T17: 4342 | Y17: Aprobado
A18: 15 | B18: PC QUICK SAS | I18: PANTALLA LED PARA PC DE CAROLINA AMAYA | K18: PFE8209 | L18: 45677 | M18: 45678 | N18: 45707 | O18: 267750 | P18: 0 | Q18: 0 | R18: 267750 | S18: enero 2025 | T18: 4441 | Y18: Aprobado
A19: 16 | B19: AIR-E | I19: SERVICIO ENERGIA CRAFT BARRANQUILLA | K19: 91888743 | L19: 45678 | M19: 45678 | N19: 45678 | O19: 144670 | P19: 0 | Q19: 0 | R19: 144670 | S19: enero 2025 | T19: 4 | X19: aprobado por correo | Y19: Aprobado
A20: 17 | B20: ETIQUETAS COMERCIALES SAS | I20: ETIQUETEADORA PARA MARCAR ACTIVOS DE CRAFT | K20: FE3515 | L20: 45678 | M20: 45684 | N20: 45708 | O20: 232050 | P20: 0 | Q20: 0 | R20: 232050 | S20: enero 2025 | T20: 6325 | Y20: Aprobado
A21: 18 | B21: MULTICOPY JV ZOMAC SAS | I21: ALQUILER IMPRESORA CRAFT BUENAVENTURA | K21: FEPP6183 | L21: 45679 | M21: 45684 | N21: 45688 | O21: 196000 | P21: 0 | Q21: 0 | R21: 196000 | S21: enero 2025 | T21: 27 | Y21: Aprobado
A22: 19 | B22: MOVISTAR | I22: SERVICIO CELULARES CRAFT CARTAGENA | K22: BEC429616443 | L22: 45680 | M22: 45684 | N22: 45686 | O22: 804450 | P22: 0 | Q22: 0 | R22: 804450 | S22: enero 2025 | T22: 23 | Y22: Aprobado
A23: 20 | B23: HARDSOFT SOLUTIONS INTEGRAL SAS | I23: MANTENIMIENTO IT EN CTG | K23: HS152 | L23: 45681 | M23: 45684 | N23: 45688 | O23: 525980 | P23: 0 | Q23: 0 | R23: 525980 | S23: enero 2025 | T23: 24 | Y23: Aprobado
A24: 21 | B24: OPEN GROUP SAS | I24: camila.bravo, edwin ramirez, cambio de teclado de paola pulecio, uno que va hacer para carolina lopez y uno en stock para la persona de barranquilla | K24: FE5664 | L24: 45679 | M24: 45684 | N24: 45710 | O24: 574046 | P24: 0 | Q24: 0 | R24: 574046 | S24: enero 2025 | T24: 6325 | Y24: Aprobado
A25: 22 | B25: CASALIMPIA SA | D25: ADM | F25: Otros Gastos CASA LIMPIA PLANILLA AC OTROS | I25: SERVICIO DE ASEO GENERAL OFICINA CRAFT CARTAGENA | J25: Cartagena | K25: 1717328 | O25: 1358298 | P25: 0 | Q25: 0 | R25: 1358298 | S25: enero 2025 | T25: 25 | Y25: Aprobado
A26: 23 | B26: AAA ACUEDUCTO BARRANQUILLA | I26: SERVICIO ACUEDUCTO BARRANQUILLA | K26: 59843005 | O26: 226591 | P26: 0 | Q26: 0 | R26: 226591 | S26: enero 2025 | T26: 5 | Y26: Aprobado
A27: 24 | B27: Controles Empresariales SAS | I27: DIADEMAS 1 CAMILA BRAVO 4 EN STOCK | K27: FEI0000083772 | O27: 626350 | P27: 0 | Q27: 0 | R27: 626350 | S27: enero 2025 | T27: 6387 | Y27: Aprobado
A28: 25 | B28: JOAQUIN ALARCON | I28: ARREGLOS LOCATIVOS AEROPUERTO | K28: 24 | L28: 45686 | M28: 45686 | N28: 45688 | O28: 800000 | P28: 0 | Q28: 0 | R28: 800000 | S28: enero 2025 | T28: 6 | Y28: Aprobado
A29: 26 | B29: TIGO | I29: SERVICIO TELEFONIA FIJA SUC CRAFT MEDELLIN | K29: BOPU115668512 | L29: 45687 | M29: 45687 | N29: 45703 | O29: 109457 | P29: 0 | Q29: 0 | R29: 109457 | S29: enero 2025 | T29: 74 | Y29: Aprobado
A30: 27 | B30: TIGO | I30: SERVICIO DE NUMERO UNICO SUC CRAFT MEDELLIN | K30: BOPU115605001 | L30: 45687 | M30: 45687 | N30: 45703 | O30: 27351 | P30: 0 | Q30: 0 | R30: 27351 | S30: enero 2025 | T30: 73 | Y30: Aprobado
A31: 28 | B31: TIGO | I31: SERVICIO INTERNET SUC CRAFT MEDELLIN | K31: BOPU115616671 | L31: 45687 | M31: 45687 | N31: 45703 | O31: 131449 | P31: 0 | Q31: 0 | R31: 131449 | S31: enero 2025 | T31: 72 | Y31: Aprobado
A32: 29 | B32: MOVISTAR | I32: REPOSICION SIMCARD 3160231961 EN STOCK | K32: BEV21329050 | L32: 45687 | N32: 45702 | O32: 8000 | P32: 0 | Q32: 0 | R32: 8000 | S32: enero 2025 | T32: 7368 | Y32: Aprobado
A33: 30 | B33: OPERADORA HOTELERA PORTUS SAS | I33: ALOJAMIENTO EN CARTAGENA OLGA MONTOYA | K33: FEHM43364 | L33: 45702 | M33: 45705 | N33: 45732 | O33: 1356600 | P33: 0 | Q33: 0 | R33: 1356600 | S33: febrero 2025 | T33: 32 | Y33: Aprobado
A34: 31 | B34: PC QUICK SAS | I34: 2 PC / MEMORIAS GINNA CASTRO Y SEBASTIAN PEREZ | K34: PFE8349 | L34: 45702 | M34: 45705 | N34: 45732 | O34: 4680880 | P34: 0 | Q34: 0 | R34: 4680880 | S34: febrero 2025 | T34: 5530 | Y34: Aprobado
A35: 32 | B35: CONTRATOS Y FIANZAS DE ARRENDAMIENTO S.A.S. | D35: ADM | F35: Arriendos | I35: SERVICIO ZONA VIRTUAL CRAFT MEDELLIN | J35: Medellín | K35: FE566213 | L35: 45702 | M35: 45705 | N35: 45709 | O35: 5200 | P35: 0 | Q35: 0 | R35: 5200 | S35: febrero 2025 | T35: 97 | Y35: Aprobado
A36: 33 | B36: AIR-E | I36: SERVICIO ENERGIA CRAFT BARRANQUILLA | K36: 93439397 | L36: 45705 | M36: 45705 | N36: 45706 | O36: 547310 | P36: 0 | Q36: 0 | R36: 547310 | S36: febrero 2025 | T36: 3 | Y36: Aprobado
A37: 34 | B37: EPM MEDELLIN | I37: SERVICIOS PUBLICOS CRAFT MEDELLIN | K37: DEE9073074 | L37: 45705 | M37: 45705 | N37: 45715 | O37: 388061 | P37: 0 | Q37: 0 | R37: 388061 | S37: febrero 2025 | T37: 100 | Y37: Aprobado
A38: 35 | B38: MOVISTAR | I38: SERVICIOS CELULARES CRAFT BOGOTA | K38: BEC434656594 | L38: 45703 | M38: 45705 | N38: 45709 | O38: 1608263 | P38: 0 | Q38: 0 | R38: 1608263 | S38: febrero 2025 | T38: 5533 | Y38: Aprobado
A39: 36 | B39: JAVIER ANTONIO SANCHEZ | I39: ARRIENDO CUARTO DE BODEGA CRAFT BUENAVENTURA | K39: 202502 | L39: 45706 | M39: 45706 | N39: 45709 | O39: 250000 | P39: 0 | Q39: 0 | R39: 250000 | S39: febrero 2025 | T39: 11 | Y39: Aprobado
A40: 37 | B40: EDIFICIO PORTUS MANGA CARTAGENA | I40: PARQUEADERO EN CRAFT CARTAGENA | K40: 222 | L40: 45706 | M40: 45706 | N40: 45709 | O40: 94225 | P40: 0 | Q40: 0 | R40: 94225 | S40: febrero 2025 | T40: 20
...

Sheet ARCHIVO PLANO
A1: ARCHIVO PLANO — PARA CONTABILIDAD | Generado automáticamente desde REGISTRO
A2: N° | B2: PROVEEDOR | C2: SERVICIO | D2: ÁREA | E2: P&L | F2: CUENTA CONTABLE | G2: GLOSA | H2: DETALLE | I2: SUCURSAL | J2: N° FACTURA | K2: FECHA VENCIMIENTO | L2: GASTO NETO | M2: MES EJECUCIÓN
A3: =IF(REGISTRO!B4="","",REGISTRO!A4) | B3: =IF(REGISTRO!B4="","",REGISTRO!B4) | C3: =IF(REGISTRO!B4="","",REGISTRO!C4) | D3: =IF(REGISTRO!B4="","",REGISTRO!D4) | E3: =IF(REGISTRO!B4="","",REGISTRO!E4) | F3: =IF(REGISTRO!B4="","",REGISTRO!F4) | G3: =IF(REGISTRO!B4="","",REGISTRO!G4) | H3: =IF(REGISTRO!B4="","",REGISTRO!I4) | I3: =IF(REGISTRO!B4="","",REGISTRO!J4) | J3: =IF(REGISTRO!B4="","",REGISTRO!K4) | K3: =IF(REGISTRO!B4="","",REGISTRO!N4) | L3: =IF(REGISTRO!B4="","",REGISTRO!R4) | M3: =IF(REGISTRO!B4="","",REGISTRO!S4)
A4: =IF(REGISTRO!B4="","",REGISTRO!A4) | B4: =IF(REGISTRO!B4="","",REGISTRO!B4) | C4: =IF(REGISTRO!B4="","",REGISTRO!C4) | D4: =IF(REGISTRO!B4="","",REGISTRO!D4) | E4: =IF(REGISTRO!B4="","",REGISTRO!E4) | F4: =IF(REGISTRO!B4="","",REGISTRO!F4) | G4: =IF(REGISTRO!B4="","",REGISTRO!G4) | H4: =IF(REGISTRO!B4="","",REGISTRO!I4) | I4: =IF(REGISTRO!B4="","",REGISTRO!J4) | J4: =IF(REGISTRO!B4="","",REGISTRO!K4) | K4: =IF(REGISTRO!B4="","",REGISTRO!N4) | L4: =IF(REGISTRO!B4="","",REGISTRO!R4) | M4: =IF(REGISTRO!B4="","",REGISTRO!S4)
A5: =IF(REGISTRO!B5="","",REGISTRO!A5) | B5: =IF(REGISTRO!B5="","",REGISTRO!B5) | C5: =IF(REGISTRO!B5="","",REGISTRO!C5) | D5: =IF(REGISTRO!B5="","",REGISTRO!D5) | E5: =IF(REGISTRO!B5="","",REGISTRO!E5) | F5: =IF(REGISTRO!B5="","",REGISTRO!F5) | G5: =IF(REGISTRO!B5="","",REGISTRO!G5) | H5: =IF(REGISTRO!B5="","",REGISTRO!I5) | I5: =IF(REGISTRO!B5="","",REGISTRO!J5) | J5: =IF(REGISTRO!B5="","",REGISTRO!K5) | K5: =IF(REGISTRO!B5="","",REGISTRO!N5) | L5: =IF(REGISTRO!B5="","",REGISTRO!R5) | M5: =IF(REGISTRO!B5="","",REGISTRO!S5)
A6: =IF(REGISTRO!B6="","",REGISTRO!A6) | B6: =IF(REGISTRO!B6="","",REGISTRO!B6) | C6: =IF(REGISTRO!B6="","",REGISTRO!C6) | D6: =IF(REGISTRO!B6="","",REGISTRO!D6) | E6: =IF(REGISTRO!B6="","",REGISTRO!E6) | F6: =IF(REGISTRO!B6="","",REGISTRO!F6) | G6: =IF(REGISTRO!B6="","",REGISTRO!G6) | H6: =IF(REGISTRO!B6="","",REGISTRO!I6) | I6: =IF(REGISTRO!B6="","",REGISTRO!J6) | J6: =IF(REGISTRO!B6="","",REGISTRO!K6) | K6: =IF(REGISTRO!B6="","",REGISTRO!N6) | L6: =IF(REGISTRO!B6="","",REGISTRO!R6) | M6: =IF(REGISTRO!B6="","",REGISTRO!S6)
A7: =IF(REGISTRO!B7="","",REGISTRO!A7) | B7: =IF(REGISTRO!B7="","",REGISTRO!B7) | C7: =IF(REGISTRO!B7="","",REGISTRO!C7) | D7: =IF(REGISTRO!B7="","",REGISTRO!D7) | E7: =IF(REGISTRO!B7="","",REGISTRO!E7) | F7: =IF(REGISTRO!B7="","",REGISTRO!F7) | G7: =IF(REGISTRO!B7="","",REGISTRO!G7) | H7: =IF(REGISTRO!B7="","",REGISTRO!I7) | I7: =IF(REGISTRO!B7="","",REGISTRO!J7) | J7: =IF(REGISTRO!B7="","",REGISTRO!K7) | K7: =IF(REGISTRO!B7="","",REGISTRO!N7) | L7: =IF(REGISTRO!B7="","",REGISTRO!R7) | M7: =IF(REGISTRO!B7="","",REGISTRO!S7)
A8: =IF(REGISTRO!B8="","",REGISTRO!A8) | B8: =IF(REGISTRO!B8="","",REGISTRO!B8) | C8: =IF(REGISTRO!B8="","",REGISTRO!C8) | D8: =IF(REGISTRO!B8="","",REGISTRO!D8) | E8: =IF(REGISTRO!B8="","",REGISTRO!E8) | F8: =IF(REGISTRO!B8="","",REGISTRO!F8) | G8: =IF(REGISTRO!B8="","",REGISTRO!G8) | H8: =IF(REGISTRO!B8="","",REGISTRO!I8) | I8: =IF(REGISTRO!B8="","",REGISTRO!J8) | J8: =IF(REGISTRO!B8="","",REGISTRO!K8) | K8: =IF(REGISTRO!B8="","",REGISTRO!N8) | L8: =IF(REGISTRO!B8="","",REGISTRO!R8) | M8: =IF(REGISTRO!B8="","",REGISTRO!S8)
A9: =IF(REGISTRO!B9="","",REGISTRO!A9) | B9: =IF(REGISTRO!B9="","",REGISTRO!B9) | C9: =IF(REGISTRO!B9="","",REGISTRO!C9) | D9: =IF(REGISTRO!B9="","",REGISTRO!D9) | E9: =IF(REGISTRO!B9="","",REGISTRO!E9) | F9: =IF(REGISTRO!B9="","",REGISTRO!F9) | G9: =IF(REGISTRO!B9="","",REGISTRO!G9) | H9: =IF(REGISTRO!B9="","",REGISTRO!I9) | I9: =IF(REGISTRO!B9="","",REGISTRO!J9) | J9: =IF(REGISTRO!B9="","",REGISTRO!K9) | K9: =IF(REGISTRO!B9="","",REGISTRO!N9) | L9: =IF(REGISTRO!B9="","",REGISTRO!R9) | M9: =IF(REGISTRO!B9="","",REGISTRO!S9)
A10: =IF(REGISTRO!B10="","",REGISTRO!A10) | B10: =IF(REGISTRO!B10="","",REGISTRO!B10) | C10: =IF(REGISTRO!B10="","",REGISTRO!C10) | D10: =IF(REGISTRO!B10="","",REGISTRO!D10) | E10: =IF(REGISTRO!B10="","",REGISTRO!E10) | F10: =IF(REGISTRO!B10="","",REGISTRO!F10) | G10: =IF(REGISTRO!B10="","",REGISTRO!G10) | H10: =IF(REGISTRO!B10="","",REGISTRO!I10) | I10: =IF(REGISTRO!B10="","",REGISTRO!J10) | J10: =IF(REGISTRO!B10="","",REGISTRO!K10) | K10: =IF(REGISTRO!B10="","",REGISTRO!N10) | L10: =IF(REGISTRO!B10="","",REGISTRO!R10) | M10: =IF(REGISTRO!B10="","",REGISTRO!S10)
A11: =IF(REGISTRO!B11="","",REGISTRO!A11) | B11: =IF(REGISTRO!B11="","",REGISTRO!B11) | C11: =IF(REGISTRO!B11="","",REGISTRO!C11) | D11: =IF(REGISTRO!B11="","",REGISTRO!D11) | E11: =IF(REGISTRO!B11="","",REGISTRO!E11) | F11: =IF(REGISTRO!B11="","",REGISTRO!F11) | G11: =IF(REGISTRO!B11="","",REGISTRO!G11) | H11: =IF(REGISTRO!B11="","",REGISTRO!I11) | I11: =IF(REGISTRO!B11="","",REGISTRO!J11) | J11: =IF(REGISTRO!B11="","",REGISTRO!K11) | K11: =IF(REGISTRO!B11="","",REGISTRO!N11) | L11: =IF(REGISTRO!B11="","",REGISTRO!R11) | M11: =IF(REGISTRO!B11="","",REGISTRO!S11)
A12: =IF(REGISTRO!B12="","",REGISTRO!A12) | B12: =IF(REGISTRO!B12="","",REGISTRO!B12) | C12: =IF(REGISTRO!B12="","",REGISTRO!C12) | D12: =IF(REGISTRO!B12="","",REGISTRO!D12) | E12: =IF(REGISTRO!B12="","",REGISTRO!E12) | F12: =IF(REGISTRO!B12="","",REGISTRO!F12) | G12: =IF(REGISTRO!B12="","",REGISTRO!G12) | H12: =IF(REGISTRO!B12="","",REGISTRO!I12) | I12: =IF(REGISTRO!B12="","",REGISTRO!J12) | J12: =IF(REGISTRO!B12="","",REGISTRO!K12) | K12: =IF(REGISTRO!B12="","",REGISTRO!N12) | L12: =IF(REGISTRO!B12="","",REGISTRO!R12) | M12: =IF(REGISTRO!B12="","",REGISTRO!S12)
A13: =IF(REGISTRO!B13="","",REGISTRO!A13) | B13: =IF(REGISTRO!B13="","",REGISTRO!B13) | C13: =IF(REGISTRO!B13="","",REGISTRO!C13) | D13: =IF(REGISTRO!B13="","",REGISTRO!D13) | E13: =IF(REGISTRO!B13="","",REGISTRO!E13) | F13: =IF(REGISTRO!B13="","",REGISTRO!F13) | G13: =IF(REGISTRO!B13="","",REGISTRO!G13) | H13: =IF(REGISTRO!B13="","",REGISTRO!I13) | I13: =IF(REGISTRO!B13="","",REGISTRO!J13) | J13: =IF(REGISTRO!B13="","",REGISTRO!K13) | K13: =IF(REGISTRO!B13="","",REGISTRO!N13) | L13: =IF(REGISTRO!B13="","",REGISTRO!R13) | M13: =IF(REGISTRO!B13="","",REGISTRO!S13)
A14: =IF(REGISTRO!B14="","",REGISTRO!A14) | B14: =IF(REGISTRO!B14="","",REGISTRO!B14) | C14: =IF(REGISTRO!B14="","",REGISTRO!C14) | D14: =IF(REGISTRO!B14="","",REGISTRO!D14) | E14: =IF(REGISTRO!B14="","",REGISTRO!E14) | F14: =IF(REGISTRO!B14="","",REGISTRO!F14) | G14: =IF(REGISTRO!B14="","",REGISTRO!G14) | H14: =IF(REGISTRO!B14="","",REGISTRO!I14) | I14: =IF(REGISTRO!B14="","",REGISTRO!J14) | J14: =IF(REGISTRO!B14="","",REGISTRO!K14) | K14: =IF(REGISTRO!B14="","",REGISTRO!N14) | L14: =IF(REGISTRO!B14="","",REGISTRO!R14) | M14: =IF(REGISTRO!B14="","",REGISTRO!S14)
A15: =IF(REGISTRO!B15="","",REGISTRO!A15) | B15: =IF(REGISTRO!B15="","",REGISTRO!B15) | C15: =IF(REGISTRO!B15="","",REGISTRO!C15) | D15: =IF(REGISTRO!B15="","",REGISTRO!D15) | E15: =IF(REGISTRO!B15="","",REGISTRO!E15) | F15: =IF(REGISTRO!B15="","",REGISTRO!F15) | G15: =IF(REGISTRO!B15="","",REGISTRO!G15) | H15: =IF(REGISTRO!B15="","",REGISTRO!I15) | I15: =IF(REGISTRO!B15="","",REGISTRO!J15) | J15: =IF(REGISTRO!B15="","",REGISTRO!K15) | K15: =IF(REGISTRO!B15="","",REGISTRO!N15) | L15: =IF(REGISTRO!B15="","",REGISTRO!R15) | M15: =IF(REGISTRO!B15="","",REGISTRO!S15)
... A451: =IF(REGISTRO!B451="","",REGISTRO!A451) | B451: =IF(REGISTRO!B451="","",REGISTRO!B451) | C451: =IF(REGISTRO!B451="","",REGISTRO!C451) | D451: =IF(REGISTRO!B451="","",REGISTRO!D451) | E451: =IF(REGISTRO!B451="","",REGISTRO!E451) | F451: =IF(REGISTRO!B451="","",REGISTRO!F451) | G451: =IF(REGISTRO!B451="","",REGISTRO!G451) | H451: =IF(REGISTRO!B451="","",REGISTRO!I451) | I451: =IF(REGISTRO!B451="","",REGISTRO!J451) | J451: =IF(REGISTRO!B451="","",REGISTRO!K451) | K451: =IF(REGISTRO!B451="","",REGISTRO!N451) | L451: =IF(REGISTRO!B451="","",REGISTRO!R451) | M451: =IF(REGISTRO!B451="","",REGISTRO!S451)

Sheet REGISTRO NO PAGAR
A1: REGISTRO DE FACTURAS NO PAGAR — CRAFT | Paso 1: elige PROVEEDOR → Paso 2: elige SERVICIO → completa los campos amarillos
A2: 🟨 Campos amarillos = ingreso manual | 🟩 Campos verdes = automáticos (no editar) | El SERVICIO depende del PROVEEDOR elegido | Facturas que NO se van a pagar (rechazadas / dadas de baja)
A3: N° | B3: PROVEEDOR | C3: SERVICIO | D3: ÁREA | E3: P&L | F3: CUENTA CONTABLE | G3: GLOSA | H3: TIPO | I3: DETALLE DEL GASTO | J3: SUCURSAL | K3: N° FACTURA | L3: FECHA FACTURA | M3: FECHA REALIZACIÓN EVENTOS | N3: MONTO | O3: CDC | P3: FECHA PROCESADO FINANCIERO | Q3: OBSERVACIONES | R3: APROBACIÓN GERENCIA ADMINISTRATIVA | S3: FECHA DE APROBACIÓN | T3: MES EJECUCIÓN
A4: 1 | B4: CASALIMPIA SA | D4: ADM | E4: =IF(OR(B4="",C4=""),"",IFERROR(VLOOKUP(B4&"|||"&C4,MAESTRA!$A$3:$J$500,6,0),"⚠ No encontrado")) | F4: =IF(OR(B4="",C4=""),"",IFERROR(VLOOKUP(B4&"|||"&C4,MAESTRA!$A$3:$J$500,7,0),"⚠ No encontrado")) | G4: Otros Gastos CASA LIMPIA PLANILLA AC OTROS | H4: =IF(OR(B4="",C4=""),"",IFERROR(VLOOKUP(B4&"|||"&C4,MAESTRA!$A$3:$J$500,9,0),"")) | I4: NO PAGAR LEGALIZA PAGO POR PSE ASEO OFICINA CASALIMPIA BARRANQUILLA | J4: Barranquilla | K4: AP223365 | L4: 46028 | N4: 546400 | O4: 5 | P4: 46036 | R4: APROBACIÓN GERENCIA DE PERSONAS Y ADMÓN | T4: enero 2026
A5: 2 | B5: CASALIMPIA SA | D5: ADM | E5: =IF(OR(B5="",C5=""),"",IFERROR(VLOOKUP(B5&"|||"&C5,MAESTRA!$A$3:$J$500,6,0),"⚠ No encontrado")) | F5: =IF(OR(B5="",C5=""),"",IFERROR(VLOOKUP(B5&"|||"&C5,MAESTRA!$A$3:$J$500,7,0),"⚠ No encontrado")) | G5: Otros Gastos CASA LIMPIA PLANILLA AC OTROS | H5: =IF(OR(B5="",C5=""),"",IFERROR(VLOOKUP(B5&"|||"&C5,MAESTRA!$A$3:$J$500,9,0),"")) | I5: NO PAGAR LEGALIZA PAGO POR PSE ASEO OFICINA CASALIMPIA CALI | J5: Cali | K5: AP223364 | L5: 46028 | N5: 409800 | O5: 4 | P5: 46036 | R5: APROBACIÓN GERENCIA DE PERSONAS Y ADMÓN | T5: enero 2026
A6: 3 | B6: CAMARA DE COMERCIO DE BOGOTA | D6: ADM | E6: =IF(OR(B6="",C6=""),"",IFERROR(VLOOKUP(B6&"|||"&C6,MAESTRA!$A$3:$J$500,6,0),"⚠ No encontrado")) | F6: =IF(OR(B6="",C6=""),"",IFERROR(VLOOKUP(B6&"|||"&C6,MAESTRA!$A$3:$J$500,7,0),"⚠ No encontrado")) | G6: Trámites notariales autenticaciones | H6: =IF(OR(B6="",C6=""),"",IFERROR(VLOOKUP(B6&"|||"&C6,MAESTRA!$A$3:$J$500,9,0),"")) | I6: NO PAGAR LEGALIZA CAJA MENOR BOG COMPRA DE CAMARA Y COMERCIO | J6: Calle 100 | K6: TV439715239 | L6: 46024 | N6: 12100 | O6: 1920 | P6: 46036 | R6: APROBACIÓN GERENCIA DE PERSONAS Y ADMÓN | T6: enero 2026
A7: 4 | B7: GASEOSAS LUX S.A.S. | D7: ADM | E7: =IF(OR(B7="",C7=""),"",IFERROR(VLOOKUP(B7&"|||"&C7,MAESTRA!$A$3:$J$500,6,0),"⚠ No encontrado")) | F7: =IF(OR(B7="",C7=""),"",IFERROR(VLOOKUP(B7&"|||"&C7,MAESTRA!$A$3:$J$500,7,0),"⚠ No encontrado")) | G7: Material Copa/Cozinha | H7: =IF(OR(B7="",C7=""),"",IFERROR(VLOOKUP(B7&"|||"&C7,MAESTRA!$A$3:$J$500,9,0),"")) | I7: NO PAGAR LEGALIZA CAJA MENOR AEROPUERTO COMPRA 3 BOTELLONES DE AGUA | J7: Aeropuerto | K7: GL071180399 | L7: 46030 | N7: 40050 | R7: APROBACIÓN GERENCIA DE PERSONAS Y ADMÓN | T7: enero 2026
A8: 5 | B8: OSCAR ANTONIO HERNANDEZ GOMEZ | D8: ADM | E8: =IF(OR(B8="",C8=""),"",IFERROR(VLOOKUP(B8&"|||"&C8,MAESTRA!$A$3:$J$500,6,0),"⚠ No encontrado")) | F8: =IF(OR(B8="",C8=""),"",IFERROR(VLOOKUP(B8&"|||"&C8,MAESTRA!$A$3:$J$500,7,0),"⚠ No encontrado")) | G8: Trámites notariales autenticaciones | H8: =IF(OR(B8="",C8=""),"",IFERROR(VLOOKUP(B8&"|||"&C8,MAESTRA!$A$3:$J$500,9,0),"")) | I8: NO PAGAR LEGALIZA CAJA MENOR BOGOTA AUTENTICA CONTRATO PROVEEDOR OTM DIANA CASAS | J8: Calle 100 | K8: FEV140042 | L8: 46030 | N8: 4200 | O8: 1922 | P8: 46036 | R8: APROBACIÓN GERENCIA DE PERSONAS Y ADMÓN | T8: enero 2026
A9: 6 | B9: SUPERMARKET LA COLOMBIANA SAS ZOMAC | D9: ADM | E9: =IF(OR(B9="",C9=""),"",IFERROR(VLOOKUP(B9&"|||"&C9,MAESTRA!$A$3:$J$500,6,0),"⚠ No encontrado")) | F9: =IF(OR(B9="",C9=""),"",IFERROR(VLOOKUP(B9&"|||"&C9,MAESTRA!$A$3:$J$500,7,0),"⚠ No encontrado")) | G9: Material Copa/Cozinha | H9: =IF(OR(B9="",C9=""),"",IFERROR(VLOOKUP(B9&"|||"&C9,MAESTRA!$A$3:$J$500,9,0),"")) | I9: NO PAGAR LEGALIZA CAJA MENOR BUENAVENTURA COMPRA BOTELLON DE AGUA | J9: Buenaventura | K9: SMEF42506 | L9: 46031 | N9: 30000 | O9: 8 | P9: 46036 | R9: APROBACIÓN GERENCIA DE PERSONAS Y ADMÓN | T9: enero 2026
A10: 7 | B10: OSCAR ANTONIO HERNANDEZ GOMEZ | D10: ADM | E10: =IF(OR(B10="",C10=""),"",IFERROR(VLOOKUP(B10&"|||"&C10,MAESTRA!$A$3:$J$500,6,0),"⚠ No encontrado")) | F10: =IF(OR(B10="",C10=""),"",IFERROR(VLOOKUP(B10&"|||"&C10,MAESTRA!$A$3:$J$500,7,0),"⚠ No encontrado")) | G10: Trámites notariales autenticaciones | H10: =IF(OR(B10="",C10=""),"",IFERROR(VLOOKUP(B10&"|||"&C10,MAESTRA!$A$3:$J$500,9,0),"")) | I10: NO PAGAR LEGALIZA CAJA MENOR BOGOTA AUTENTICA CARTAS MAERSK SILVIA TRIANA | J10: Calle 100 | K10: FEV140166 | L10: 46031 | N10: 14137 | O10: 1926 | P10: 46036 | R10: APROBACIÓN GERENCIA DE PERSONAS Y ADMÓN | T10: enero 2026
A11: 8 | B11: COLOMBIANA DE COMERCIO S.A. | D11: GH | E11: =IF(OR(B11="",C11=""),"",IFERROR(VLOOKUP(B11&"|||"&C11,MAESTRA!$A$3:$J$500,6,0),"⚠ No encontrado")) | F11: =IF(OR(B11="",C11=""),"",IFERROR(VLOOKUP(B11&"|||"&C11,MAESTRA!$A$3:$J$500,7,0),"⚠ No encontrado")) | G11: Plan estratégico en enero 2025 | H11: =IF(OR(B11="",C11=""),"",IFERROR(VLOOKUP(B11&"|||"&C11,MAESTRA!$A$3:$J$500,9,0),"")) | I11: NO PAGAR LEGALIZA CAJA MENOR BOGOTA COMPRA VASOS Y PAPEL SANDWICH DESAYUNO HEAD | J11: Transversal | K11: X9222557543 | L11: 46034 | N11: 28700 | O11: 1928 | P11: 46036 | R11: APROBACIÓN GERENCIA DE PERSONAS Y ADMÓN | T11: enero 2026
A12: 9 | B12: CADENA COMERCIAL OXXO COLOMBIA S A S | D12: GH | E12: =IF(OR(B12="",C12=""),"",IFERROR(VLOOKUP(B12&"|||"&C12,MAESTRA!$A$3:$J$500,6,0),"⚠ No encontrado")) | F12: =IF(OR(B12="",C12=""),"",IFERROR(VLOOKUP(B12&"|||"&C12,MAESTRA!$A$3:$J$500,7,0),"⚠ No encontrado")) | G12: Plan estratégico en enero 2025 | H12: =IF(OR(B12="",C12=""),"",IFERROR(VLOOKUP(B12&"|||"&C12,MAESTRA!$A$3:$J$500,9,0),"")) | I12: NO PAGAR LEGALIZA TC 9994 COMPRA GASEOSA ALMUERZO REUNION HEAD | J12: Transversal | K12: 234C210864 | L12: 46035 | N12: 54400 | O12: 1929 | P12: 46036 | R12: APROBACIÓN GERENCIA DE PERSONAS Y ADMÓN | T12: enero 2026
A13: 10 | B13: COORSERPARK S.A.S | D13: GH | E13: =IF(OR(B13="",C13=""),"",IFERROR(VLOOKUP(B13&"|||"&C13,MAESTRA!$A$3:$J$500,6,0),"⚠ No encontrado")) | F13: =IF(OR(B13="",C13=""),"",IFERROR(VLOOKUP(B13&"|||"&C13,MAESTRA!$A$3:$J$500,7,0),"⚠ No encontrado")) | G13: Detalles en momentos especificos (Matrimonio, grados, fallecimientos) | H13: =IF(OR(B13="",C13=""),"",IFERROR(VLOOKUP(B13&"|||"&C13,MAESTRA!$A$3:$J$500,9,0),"")) | I13: NO PAGAR LEGALIZA TC 9994 ARREGLO FLORAL DIANA GRACIA | J13: Transversal | K13: SER312797 | L13: 46031 | N13: 250000 | O13: 5 | P13: 46036 | R13: APROBACIÓN GERENCIA DE PERSONAS Y ADMÓN | T13: enero 2026
A14: 11 | B14: CADENA COMERCIAL OXXO COLOMBIA S A S | D14: GH | E14: =IF(OR(B14="",C14=""),"",IFERROR(VLOOKUP(B14&"|||"&C14,MAESTRA!$A$3:$J$500,6,0),"⚠ No encontrado")) | F14: =IF(OR(B14="",C14=""),"",IFERROR(VLOOKUP(B14&"|||"&C14,MAESTRA!$A$3:$J$500,7,0),"⚠ No encontrado")) | G14: Plan estratégico en enero 2025 | H14: =IF(OR(B14="",C14=""),"",IFERROR(VLOOKUP(B14&"|||"&C14,MAESTRA!$A$3:$J$500,9,0),"")) | I14: NO PAGAR LEGALIZA TC 9994 COMPRA AGUA REUNION HEAD | J14: Transversal | K14: 334C240525 | L14: 46035 | N14: 81600 | O14: 1930 | P14: 46036 | R14: APROBACIÓN GERENCIA DE PERSONAS Y ADMÓN | T14: enero 2026
A15: 12 | B15: GRUPO CBC S.A.S. | D15: GH | E15: =IF(OR(B15="",C15=""),"",IFERROR(VLOOKUP(B15&"|||"&C15,MAESTRA!$A$3:$J$500,6,0),"⚠ No encontrado")) | F15: =IF(OR(B15="",C15=""),"",IFERROR(VLOOKUP(B15&"|||"&C15,MAESTRA!$A$3:$J$500,7,0),"⚠ No encontrado")) | G15: Café / Almuerzo con colaboradores | H15: =IF(OR(B15="",C15=""),"",IFERROR(VLOOKUP(B15&"|||"&C15,MAESTRA!$A$3:$J$500,9,0),"")) | I15: NO PAGAR LEGALIZA GINNA CASTRO ALMUERZO TRABAJO AURA,MARIANA,AACR | J15: Calle 100 | K15: A118120840 | L15: 46038 | N15: 186351 | O15: 7281 | P15: 46059 | R15: APROBACIÓN GERENCIA DE PERSONAS Y ADMÓN | T15: enero 2026
A16: 13 | B16: CADENA COMERCIAL OXXO COLOMBIA S A S | D16: GH | E16: =IF(OR(B16="",C16=""),"",IFERROR(VLOOKUP(B16&"|||"&C16,MAESTRA!$A$3:$J$500,6,0),"⚠ No encontrado")) | F16: =IF(OR(B16="",C16=""),"",IFERROR(VLOOKUP(B16&"|||"&C16,MAESTRA!$A$3:$J$500,7,0),"⚠ No encontrado")) | G16: Plan estratégico en enero 2025 | H16: =IF(OR(B16="",C16=""),"",IFERROR(VLOOKUP(B16&"|||"&C16,MAESTRA!$A$3:$J$500,9,0),"")) | I16: NO PAGAR LEGALIZA CAJA MENOR BOG COMPRA QUESOS REUNION VENTAS | J16: Transversal | K16: 334C243538 | L16: 46041 | N16: 34800 | O16: 7288 | P16: 46059 | R16: APROBACIÓN GERENCIA DE PERSONAS Y ADMÓN | T16: enero 2026
A17: 14 | B17: CADENA COMERCIAL OXXO COLOMBIA S A S | D17: GH | E17: =IF(OR(B17="",C17=""),"",IFERROR(VLOOKUP(B17&"|||"&C17,MAESTRA!$A$3:$J$500,6,0),"⚠ No encontrado")) | F17: =IF(OR(B17="",C17=""),"",IFERROR(VLOOKUP(B17&"|||"&C17,MAESTRA!$A$3:$J$500,7,0),"⚠ No encontrado")) | G17: Plan estratégico en enero 2025 | H17: =IF(OR(B17="",C17=""),"",IFERROR(VLOOKUP(B17&"|||"&C17,MAESTRA!$A$3:$J$500,9,0),"")) | I17: NO PAGAR LEGALIZA CAJA MENOR BOG COMPRA AGUAS REUNION VENTAS | J17: Transversal | K17: 234C212340 | L17: 46041 | N17: 41400 | O17: 7289 | P17: 46059 | R17: APROBACIÓN GERENCIA DE PERSONAS Y ADMÓN | T17: enero 2026
A18: 15 | B18: SUPERMARKET LA COLOMBIANA SAS ZOMAC | D18: ADM | E18: =IF(OR(B18="",C18=""),"",IFERROR(VLOOKUP(B18&"|||"&C18,MAESTRA!$A$3:$J$500,6,0),"⚠ No encontrado")) | F18: =IF(OR(B18="",C18=""),"",IFERROR(VLOOKUP(B18&"|||"&C18,MAESTRA!$A$3:$J$500,7,0),"⚠ No encontrado")) | G18: Comidas de trabajo extra colaboradores | H18: =IF(OR(B18="",C18=""),"",IFERROR(VLOOKUP(B18&"|||"&C18,MAESTRA!$A$3:$J$500,9,0),"")) | I18: NO PAGAR LEGALIZA CAJA MENOR BUENAVENTURA COMPRA GASEOSA | J18: Buenaventura | K18: SMEF43854 | L18: 46038 | N18: 10500 | O18: 25 | P18: 46059 | R18: APROBACIÓN GERENCIA DE PERSONAS Y ADMÓN | T18: enero 2026
A19: 16 | B19: ALMACENES ÉXITO S.A | D19: ADM | E19: =IF(OR(B19="",C19=""),"",IFERROR(VLOOKUP(B19&"|||"&C19,MAESTRA!$A$3:$J$500,6,0),"⚠ No encontrado")) | F19: =IF(OR(B19="",C19=""),"",IFERROR(VLOOKUP(B19&"|||"&C19,MAESTRA!$A$3:$J$500,7,0),"⚠ No encontrado")) | G19: Material Copa/Cozinha | H19: =IF(OR(B19="",C19=""),"",IFERROR(VLOOKUP(B19&"|||"&C19,MAESTRA!$A$3:$J$500,9,0),"")) | I19: NO PAGAR LEGALIZA NADIA MARTINEZ COMPRA ELEMENTOS ASEO SUCURSAL BARRANQUILLLA | J19: Barranquilla | K19: VF2711438 | L19: 46035 | N19: 251472 | O19: 7 | P19: 46051 | R19: APROBACIÓN GERENCIA DE PERSONAS Y ADMÓN | T19: enero 2026
A20: 17 | B20: GASEOSAS LUX S.A.S. | D20: ADM | E20: =IF(OR(B20="",C20=""),"",IFERROR(VLOOKUP(B20&"|||"&C20,MAESTRA!$A$3:$J$500,6,0),"⚠ No encontrado")) | F20: =IF(OR(B20="",C20=""),"",IFERROR(VLOOKUP(B20&"|||"&C20,MAESTRA!$A$3:$J$500,7,0),"⚠ No encontrado")) | G20: Material Copa/Cozinha | H20: =IF(OR(B20="",C20=""),"",IFERROR(VLOOKUP(B20&"|||"&C20,MAESTRA!$A$3:$J$500,9,0),"")) | I20: NO PAGAR LEGALIZA CAJA MENOR AEROPUERTO COMPRA BOTELLONES DE AGUA | J20: Aeropuerto | K20: GL071228596 | L20: 46043 | N20: 40050 | R20: APROBACIÓN GERENCIA DE PERSONAS Y ADMÓN | T20: enero 2026
A21: 18 | B21: COMIDAS VARPEL SAS | D21: GH | E21: =IF(OR(B21="",C21=""),"",IFERROR(VLOOKUP(B21&"|||"&C21,MAESTRA!$A$3:$J$500,6,0),"⚠ No encontrado")) | F21: =IF(OR(B21="",C21=""),"",IFERROR(VLOOKUP(B21&"|||"&C21,MAESTRA!$A$3:$J$500,7,0),"⚠ No encontrado")) | G21: Plan estratégico en enero 2025 | H21: =IF(OR(B21="",C21=""),"",IFERROR(VLOOKUP(B21&"|||"&C21,MAESTRA!$A$3:$J$500,9,0),"")) | I21: NO PAGAR LEGALIZA TC BB 9994 ALMUERZO REUNION HEAD 2 | J21: Transversal | K21: E07A67636 | L21: 46048 | N21: 615000 | O21: 7294 | P21: 46059 | R21: APROBACIÓN GERENCIA DE PERSONAS Y ADMÓN | T21: enero 2026
A22: 19 | B22: SUPERMARKET LA COLOMBIANA SAS ZOMAC | D22: ADM | E22: =IF(OR(B22="",C22=""),"",IFERROR(VLOOKUP(B22&"|||"&C22,MAESTRA!$A$3:$J$500,6,0),"⚠ No encontrado")) | F22: =IF(OR(B22="",C22=""),"",IFERROR(VLOOKUP(B22&"|||"&C22,MAESTRA!$A$3:$J$500,7,0),"⚠ No encontrado")) | G22: Material Copa/Cozinha | H22: =IF(OR(B22="",C22=""),"",IFERROR(VLOOKUP(B22&"|||"&C22,MAESTRA!$A$3:$J$500,9,0),"")) | I22: NO PAGAR LEGALIZA CAJA MENOR BUENAVENTURA COMPRA BOTELLONES DE AGUA | J22: Buenaventura | K22: SMEF45396 | L22: 46048 | N22: 30000 | O22: 26 | P22: 46059 | R22: APROBACIÓN GERENCIA DE PERSONAS Y ADMÓN | T22: enero 2026
A23: 20 | B23: COMIDAS VARPEL SAS | D23: GH | E23: =IF(OR(B23="",C23=""),"",IFERROR(VLOOKUP(B23&"|||"&C23,MAESTRA!$A$3:$J$500,6,0),"⚠ No encontrado")) | F23: =IF(OR(B23="",C23=""),"",IFERROR(VLOOKUP(B23&"|||"&C23,MAESTRA!$A$3:$J$500,7,0),"⚠ No encontrado")) | G23: Plan estratégico en enero 2025 | H23: =IF(OR(B23="",C23=""),"",IFERROR(VLOOKUP(B23&"|||"&C23,MAESTRA!$A$3:$J$500,9,0),"")) | I23: NO PAGAR LEGALIZA TC 9994 COMPRA ALMUERZO REUNION VENTAS CON AACR | J23: Transversal | K23: E07A65981 | L23: 46041 | N23: 388200 | O23: 7303 | P23: 46059 | R23: APROBACIÓN GERENCIA DE PERSONAS Y ADMÓN | T23: enero 2026
A24: 21 | B24: LISDEY MARYORY CARDONA OSPINA | D24: ADM | E24: =IF(OR(B24="",C24=""),"",IFERROR(VLOOKUP(B24&"|||"&C24,MAESTRA!$A$3:$J$500,6,0),"⚠ No encontrado")) | F24: =IF(OR(B24="",C24=""),"",IFERROR(VLOOKUP(B24&"|||"&C24,MAESTRA!$A$3:$J$500,7,0),"⚠ No encontrado")) | G24: Material Copa/Cozinha | H24: =IF(OR(B24="",C24=""),"",IFERROR(VLOOKUP(B24&"|||"&C24,MAESTRA!$A$3:$J$500,9,0),"")) | I24: NO PAGAR LEGALIZA CAJA MENOR CARTGENA COMPRA BOTELLONES DE AGUA | J24: Cartagena | K24: FELM31652 | L24: 46043 | N24: 18000 | O24: 36 | P24: 46059 | R24: APROBACIÓN GERENCIA DE PERSONAS Y ADMÓN | T24: enero 2026
A25: 22 | B25: GRUPO CBC S.A.S. | D25: GH | E25: =IF(OR(B25="",C25=""),"",IFERROR(VLOOKUP(B25&"|||"&C25,MAESTRA!$A$3:$J$500,6,0),"⚠ No encontrado")) | F25: =IF(OR(B25="",C25=""),"",IFERROR(VLOOKUP(B25&"|||"&C25,MAESTRA!$A$3:$J$500,7,0),"⚠ No encontrado")) | G25: Café / Almuerzo con colaboradores | H25: =IF(OR(B25="",C25=""),"",IFERROR(VLOOKUP(B25&"|||"&C25,MAESTRA!$A$3:$J$500,9,0),"")) | I25: NO PAGAR LEGALIZA TC 9994 ALMUERZO DE TRABAJO AREA ADMITIVA CAMBIO PISO OF | J25: Calle 100 | K25: A22326458 | L25: 46045 | N25: 314100 | O25: 7310 | P25: 46059 | R25: APROBACIÓN GERENCIA DE PERSONAS Y ADMÓN | T25: enero 2026
A26: 23 | B26: AMERICAN LOCKS CENTER SAS | D26: ADM | E26: =IF(OR(B26="",C26=""),"",IFERROR(VLOOKUP(B26&"|||"&C26,MAESTRA!$A$3:$J$500,6,0),"⚠ No encontrado")) | F26: =IF(OR(B26="",C26=""),"",IFERROR(VLOOKUP(B26&"|||"&C26,MAESTRA!$A$3:$J$500,7,0),"⚠ No encontrado")) | G26: Material De Escritorio | H26: =IF(OR(B26="",C26=""),"",IFERROR(VLOOKUP(B26&"|||"&C26,MAESTRA!$A$3:$J$500,9,0),"")) | I26: NO PAGAR LEGALIZA TC 9994 COMPRA 3 ROLLOS VINIPEL PARA SILLAS DE OF | J26: Calle 100 | K26: FE63145 | L26: 46045 | N26: 105000 | O26: 7319 | P26: 46059 | R26: APROBACIÓN GERENCIA DE PERSONAS Y ADMÓN | T26: enero 2026
A27: 24 | B27: LISDEY MARYORY CARDONA OSPINA | D27: ADM | E27: =IF(OR(B27="",C27=""),"",IFERROR(VLOOKUP(B27&"|||"&C27,MAESTRA!$A$3:$J$500,6,0),"⚠ No encontrado")) | F27: =IF(OR(B27="",C27=""),"",IFERROR(VLOOKUP(B27&"|||"&C27,MAESTRA!$A$3:$J$500,7,0),"⚠ No encontrado")) | G27: Material Copa/Cozinha | H27: =IF(OR(B27="",C27=""),"",IFERROR(VLOOKUP(B27&"|||"&C27,MAESTRA!$A$3:$J$500,9,0),"")) | I27: NO PAGAR LEGALIZA CAJA MENOR CARTGENA COMPRA BOTELLONES DE AGUA | J27: Cartagena | K27: FELM31912 | L27: 46048 | N27: 18000 | O27: 37 | P27: 46059 | R27: APROBACIÓN GERENCIA DE PERSONAS Y ADMÓN | T27: enero 2026
A28: 25 | B28: CREPES Y WAFFLES S A | D28: GH | E28: =IF(OR(B28="",C28=""),"",IFERROR(VLOOKUP(B28&"|||"&C28,MAESTRA!$A$3:$J$500,6,0),"⚠ No encontrado")) | F28: =IF(OR(B28="",C28=""),"",IFERROR(VLOOKUP(B28&"|||"&C28,MAESTRA!$A$3:$J$500,7,0),"⚠ No encontrado")) | G28: Plan estratégico en enero 2025 | H28: =IF(OR(B28="",C28=""),"",IFERROR(VLOOKUP(B28&"|||"&C28,MAESTRA!$A$3:$J$500,9,0),"")) | I28: NO PAGAR LEGALIZA CAJA MENOR BOGOTA ALMUERZO ACCR REUNION HEAD 2 | J28: Calle 100 | K28: R06E462207 | L28: 46048 | N28: 47900 | O28: 7333 | P28: 46059 | R28: APROBACIÓN GERENCIA DE PERSONAS Y ADMÓN | T28: enero 2026
A29: 26 | B29: JOHAN DANIEL ESTUPIAN CARDENAS | D29: ADM | E29: =IF(OR(B29="",C29=""),"",IFERROR(VLOOKUP(B29&"|||"&C29,MAESTRA!$A$3:$J$500,6,0),"⚠ No encontrado")) | F29: =IF(OR(B29="",C29=""),"",IFERROR(VLOOKUP(B29&"|||"&C29,MAESTRA!$A$3:$J$500,7,0),"⚠ No encontrado")) | G29: Conservacion Y Manutenimiento De Oficina | H29: =IF(OR(B29="",C29=""),"",IFERROR(VLOOKUP(B29&"|||"&C29,MAESTRA!$A$3:$J$500,9,0),"")) | I29: NO PAGAR LEGALIZA CAJA MENOR BUENAVENTURA COMPRA CHAPA PUERTA BAÑO | J29: Buenaventura | K29: FAC1937 | L29: 46049 | N29: 80000 | O29: 27 | P29: 46059 | R29: APROBACIÓN GERENCIA DE PERSONAS Y ADMÓN | T29: enero 2026
A30: 27 | B30: PRODUCTOS PARA EL ALMA SAS | D30: ADM | E30: =IF(OR(B30="",C30=""),"",IFERROR(VLOOKUP(B30&"|||"&C30,MAESTRA!$A$3:$J$500,6,0),"⚠ No encontrado")) | F30: =IF(OR(B30="",C30=""),"",IFERROR(VLOOKUP(B30&"|||"&C30,MAESTRA!$A$3:$J$500,7,0),"⚠ No encontrado")) | G30: Reuniones gerenciales CEM (Comida) | H30: =IF(OR(B30="",C30=""),"",IFERROR(VLOOKUP(B30&"|||"&C30,MAESTRA!$A$3:$J$500,9,0),"")) | I30: NO PAGAR LEGALIZA TC 9994 DESAYUNO CEM DE ENERO | J30: Calle 100 | K30: FEJC24141 | L30: 46050 | N30: 112000 | O30: 7340 | P30: 46059 | R30: APROBACIÓN GERENCIA DE PERSONAS Y ADMÓN | T30: enero 2026
A31: 28 | B31: FIT CHOICES COMPANY S.A.S | D31: ADM | E31: =IF(OR(B31="",C31=""),"",IFERROR(VLOOKUP(B31&"|||"&C31,MAESTRA!$A$3:$J$500,6,0),"⚠ No encontrado")) | F31: =IF(OR(B31="",C31=""),"",IFERROR(VLOOKUP(B31&"|||"&C31,MAESTRA!$A$3:$J$500,7,0),"⚠ No encontrado")) | G31: Gastos De Representacion | H31: =IF(OR(B31="",C31=""),"",IFERROR(VLOOKUP(B31&"|||"&C31,MAESTRA!$A$3:$J$500,9,0),"")) | I31: NO PAGAR LEGALIZA NADIA MARTINEZ DESAYUNO CLIENTE ANDES | J31: Barranquilla | K31: FIT57997 | L31: 46044 | N31: 119800 | O31: 8 | P31: 46051 | R31: APROBACIÓN GERENCIA DE PERSONAS Y ADMÓN | T31: enero 2026
A32: 29 | B32: CASALIMPIA SA | D32: ADM | E32: =IF(OR(B32="",C32=""),"",IFERROR(VLOOKUP(B32&"|||"&C32,MAESTRA!$A$3:$J$500,6,0),"⚠ No encontrado")) | F32: =IF(OR(B32="",C32=""),"",IFERROR(VLOOKUP(B32&"|||"&C32,MAESTRA!$A$3:$J$500,7,0),"⚠ No encontrado")) | G32: Otros Gastos CASA LIMPIA PLANILLA AC OTROS | H32: =IF(OR(B32="",C32=""),"",IFERROR(VLOOKUP(B32&"|||"&C32,MAESTRA!$A$3:$J$500,9,0),"")) | I32: NO PAGAR LEGALIZA TC 9994 ASEO OFICINA CRAFT BARRANQUILLA | J32: Barranquilla | K32: AP225405 | L32: 46052 | N32: 491760 | O32: 9 | P32: 46059 | R32: APROBACIÓN GERENCIA DE PERSONAS Y ADMÓN | T32: enero 2026
... A38: 35 | B38: BAGATELLE S.A.S. | D38: ADM | E38: =IF(OR(B38="",C38=""),"",IFERROR(VLOOKUP(B38&"|||"&C38,MAESTRA!$A$3:$J$500,6,0),"⚠ No encontrado")) | F38: =IF(OR(B38="",C38=""),"",IFERROR(VLOOKUP(B38&"|||"&C38,MAESTRA!$A$3:$J$500,7,0),"⚠ No encontrado")) | G38: Gastos De Representacion | H38: =IF(OR(B38="",C38=""),"",IFERROR(VLOOKUP(B38&"|||"&C38,MAESTRA!$A$3:$J$500,9,0),"")) | I38: NO PAGAR LEGALIZA TC 0206 DESAYUNO CLIENTE MSL CON AACR | J38: Calle 100 | K38: B2198377 | L38: 46041 | N38: 182659 | O38: 7367 | P38: 46059 | R38: APROBACIÓN GERENCIA DE PERSONAS Y ADMÓN | T38: enero 2026
A39: 36 | B39: SEGUROS BOLIVAR | D39: GH | E39: =IF(OR(B39="",C39=""),"",IFERROR(VLOOKUP(B39&"|||"&C39,MAESTRA!$A$3:$J$500,6,0),"⚠ No encontrado")) | F39: =IF(OR(B39="",C39=""),"",IFERROR(VLOOKUP(B39&"|||"&C39,MAESTRA!$A$3:$J$500,7,0),"⚠ No encontrado")) | G39: =IF(OR(B39="",C39=""),"",IFERROR(VLOOKUP(B39&"|||"&C39,MAESTRA!$A$3:$J$500,8,0),"⚠ No encontrado")) | H39: =IF(OR(B39="",C39=""),"",IFERROR(VLOOKUP(B39&"|||"&C39,MAESTRA!$A$3:$J$500,9,0),"")) | I39: NO PAGAR FACTURA APORTES REALIZADOS A ARL AÑO 2025 | J39: Calle 100 | K39: POL15783488 | L39: 46037 | N39: 10586700 | R39: APROBACIÓN GERENCIA DE PERSONAS Y ADMÓN | T39: enero 2026
A40: 37 | B40: PANAMERICANA LIBRERÍA Y PAPELERÍA S.A. | D40: IT | E40: =IF(OR(B40="",C40=""),"",IFERROR(VLOOKUP(B40&"|||"&C40,MAESTRA!$A$3:$J$500,6,0),"⚠ No encontrado")) | F40: =IF(OR(B40="",C40=""),"",IFERROR(VLOOKUP(B40&"|||"&C40,MAESTRA!$A$3:$J$500,7,0),"⚠ No encontrado")) | G40: Insumos y perifericos | H40: =IF(OR(B40="",C40=""),"",IFERROR(VLOOKUP(B40&"|||"&C40,MAESTRA!$A$3:$J$500,9,0),"")) | I40: NO PAGAR LEGALIZA CAJA MENOR CTG COMPRA MOUSE Y TECLADO OF CTG | J40: Cartagena | K40: 29E732573 | L40: 46043 | N40: 79900 | O40: 38 | P40: 46059 | R40: APROBACIÓN GERENCIA DE PERSONAS Y ADMÓN | T40: enero 2026
A41: 38 | B41: CREPES Y WAFFLES S A | D41: GH | E41: =IF(OR(B41="",C41=""),"",IFERROR(VLOOKUP(B41&"|||"&C41,MAESTRA!$A$3:$J$500,6,0),"⚠ No encontrado")) | F41: =IF(OR(B41="",C41=""),"",IFERROR(VLOOKUP(B41&"|||"&C41,MAESTRA!$A$3:$J$500,7,0),"⚠ No encontrado")) | G41: Cumpleaños | H41: =IF(OR(B41="",C41=""),"",IFERROR(VLOOKUP(B41&"|||"&C41,MAESTRA!$A$3:$J$500,9,0),"")) | I41: NO PAGAR LEGALIZA MARIANA MUNAR, HELADOS DE CUMPLEAÑOS MARIANA SOTELO, SOFIA TORRES Y EDWIN RAMIREZ | J41: Transversal | K41: R06E466439 | L41: 46057 | N41: 49100 | O41: 2001 | P41: 46065 | R41: APROBACIÓN GERENCIA DE PERSONAS Y ADMÓN | T41: febrero 2026
A42: 39 | B42: CADENA COMERCIAL OXXO COLOMBIA S A S | D42: ADM | E42: =IF(OR(B42="",C42=""),"",IFERROR(VLOOKUP(B42&"|||"&C42,MAESTRA!$A$3:$J$500,6,0),"⚠ No encontrado")) | F42: =IF(OR(B42="",C42=""),"",IFERROR(VLOOKUP(B42&"|||"&C42,MAESTRA!$A$3:$J$500,7,0),"⚠ No encontrado")) | G42: Reuniones gerenciales CEM (Comida) | H42: =IF(OR(B42="",C42=""),"",IFERROR(VLOOKUP(B42&"|||"&C42,MAESTRA!$A$3:$J$500,9,0),"")) | I42: NO PAGAR LEGALIZA CAJA MENOR BOGOTA COMPRA AGUA CEM | J42: Transversal | K42: 334C247688 | L42: 46050 | N42: 13600 | O42: 7364 | P42: 46059 | R42: APROBACIÓN GERENCIA DE PERSONAS Y ADMÓN | T42: enero 2026
A43: 40 | B43: GASEOSAS LUX S.A.S. | D43: ADM | E43: =IF(OR(B43="",C43=""),"",IFERROR(VLOOKUP(B43&"|||"&C43,MAESTRA!$A$3:$J$500,6,0),"⚠ No encontrado")) | F43: =IF(OR(B43="",C43=""),"",IFERROR(VLOOKUP(B43&"|||"&C43,MAESTRA!$A$3:$J$500,7,0),"⚠ No encontrado")) | G43: Material Copa/Cozinha | H43: =IF(OR(B43="",C43=""),"",IFERROR(VLOOKUP(B43&"|||"&C43,MAESTRA!$A$3:$J$500,9,0),"")) | I43: NO PAGAR LEGALIZA CAJA MENOR AEROPUERTO COMPRA 2 BOTELLONES DE AGUA | J43: Aeropuerto | K43: GL071282956 | L43: 46058 | N43: 26700 | R43: APROBACIÓN GERENCIA DE PERSONAS Y ADMÓN | T43: febrero 2026
A44: 41 | B44: CAMARA DE COMERCIO DE BOGOTA | D44: ADM | E44: =IF(OR(B44="",C44=""),"",IFERROR(VLOOKUP(B44&"|||"&C44,MAESTRA!$A$3:$J$500,6,0),"⚠ No encontrado")) | F44: =IF(OR(B44="",C44=""),"",IFERROR(VLOOKUP(B44&"|||"&C44,MAESTRA!$A$3:$J$500,7,0),"⚠ No encontrado")) | G44: Trámites notariales autenticaciones | H44: =IF(OR(B44="",C44=""),"",IFERROR(VLOOKUP(B44&"|||"&C44,MAESTRA!$A$3:$J$500,9,0),"")) | I44: NO PAGAR LEGALIZA CAJA MENOR BOGOTA COMPRA CERTIFICADO CMRA CIO CRAFT | J44: Calle 100 | K44: TV439865226 | L44: 46057 | N44: 12100 | O44: 2004 | P44: 46065 | R44: APROBACIÓN GERENCIA DE PERSONAS Y ADMÓN | T44: febrero 2026
A45: 42 | B45: SUPERMARKET LA COLOMBIANA SAS ZOMAC | D45: ADM | E45: =IF(OR(B45="",C45=""),"",IFERROR(VLOOKUP(B45&"|||"&C45,MAESTRA!$A$3:$J$500,6,0),"⚠ No encontrado")) | F45: =IF(OR(B45="",C45=""),"",IFERROR(VLOOKUP(B45&"|||"&C45,MAESTRA!$A$3:$J$500,7,0),"⚠ No encontrado")) | G45: Material Copa/Cozinha | H45: =IF(OR(B45="",C45=""),"",IFERROR(VLOOKUP(B45&"|||"&C45,MAESTRA!$A$3:$J$500,9,0),"")) | I45: NO PAGAR LEGALIZA CAJA MENOR BUENAVENTURA COMPRA BOTELLON DE AGUA | J45: Buenaventura | K45: SMEF46966 | L45: 46059 | N45: 30000 | O45: 13 | P45: 46065 | R45: APROBACIÓN GERENCIA DE PERSONAS Y ADMÓN | T45: febrero 2026
...

Sheet ARCHIVO PLANO NO PAGAR
A1: ARCHIVO PLANO NO PAGAR — PARA CONTABILIDAD | Generado automáticamente desde REGISTRO NO PAGAR
A3: N° | B3: Proveedor | C3: Servicio | D3: Área | E3: P&L | F3: Cuenta Contable | G3: Glosa | H3: Detalle del Gasto | I3: Sucursal | J3: N° Factura | K3: Fecha Realización Eventos | L3: Monto | M3: Mes Ejecución
A4: =IF('REGISTRO NO PAGAR'!B4="","",'REGISTRO NO PAGAR'!A4) | B4: =IF('REGISTRO NO PAGAR'!B4="","",'REGISTRO NO PAGAR'!B4) | C4: =IF('REGISTRO NO PAGAR'!B4="","",'REGISTRO NO PAGAR'!C4) | D4: =IF('REGISTRO NO PAGAR'!B4="","",'REGISTRO NO PAGAR'!D4) | E4: =IF('REGISTRO NO PAGAR'!B4="","",'REGISTRO NO PAGAR'!E4) | F4: =IF('REGISTRO NO PAGAR'!B4="","",'REGISTRO NO PAGAR'!F4) | G4: =IF('REGISTRO NO PAGAR'!B4="","",'REGISTRO NO PAGAR'!G4) | H4: =IF('REGISTRO NO PAGAR'!B4="","",'REGISTRO NO PAGAR'!I4) | I4: =IF('REGISTRO NO PAGAR'!B4="","",'REGISTRO NO PAGAR'!J4) | J4: =IF('REGISTRO NO PAGAR'!B4="","",'REGISTRO NO PAGAR'!K4) | K4: =IF('REGISTRO NO PAGAR'!B4="","",'REGISTRO NO PAGAR'!M4) | L4: =IF('REGISTRO NO PAGAR'!B4="","",'REGISTRO NO PAGAR'!N4) | M4: =IF('REGISTRO NO PAGAR'!B4="","",'REGISTRO NO PAGAR'!T4)
A5: =IF('REGISTRO NO PAGAR'!B5="","",'REGISTRO NO PAGAR'!A5) | B5: =IF('REGISTRO NO PAGAR'!B5="","",'REGISTRO NO PAGAR'!B5) | C5: =IF('REGISTRO NO PAGAR'!B5="","",'REGISTRO NO PAGAR'!C5) | D5: =IF('REGISTRO NO PAGAR'!B5="","",'REGISTRO NO PAGAR'!D5) | E5: =IF('REGISTRO NO PAGAR'!B5="","",'REGISTRO NO PAGAR'!E5) | F5: =IF('REGISTRO NO PAGAR'!B5="","",'REGISTRO NO PAGAR'!F5) | G5: =IF('REGISTRO NO PAGAR'!B5="","",'REGISTRO NO PAGAR'!G5) | H5: =IF('REGISTRO NO PAGAR'!B5="","",'REGISTRO NO PAGAR'!I5) | I5: =IF('REGISTRO NO PAGAR'!B5="","",'REGISTRO NO PAGAR'!J5) | J5: =IF('REGISTRO NO PAGAR'!B5="","",'REGISTRO NO PAGAR'!K5) | K5: =IF('REGISTRO NO PAGAR'!B5="","",'REGISTRO NO PAGAR'!M5) | L5: =IF('REGISTRO NO PAGAR'!B5="","",'REGISTRO NO PAGAR'!N5) | M5: =IF('REGISTRO NO PAGAR'!B5="","",'REGISTRO NO PAGAR'!T5)
A6: =IF('REGISTRO NO PAGAR'!B6="","",'REGISTRO NO PAGAR'!A6) | B6: =IF('REGISTRO NO PAGAR'!B6="","",'REGISTRO NO PAGAR'!B6) | C6: =IF('REGISTRO NO PAGAR'!B6="","",'REGISTRO NO PAGAR'!C6) | D6: =IF('REGISTRO NO PAGAR'!B6="","",'REGISTRO NO PAGAR'!D6) | E6: =IF('REGISTRO NO PAGAR'!B6="","",'REGISTRO NO PAGAR'!E6) | F6: =IF('REGISTRO NO PAGAR'!B6="","",'REGISTRO NO PAGAR'!F6) | G6: =IF('REGISTRO NO PAGAR'!B6="","",'REGISTRO NO PAGAR'!G6) | H6: =IF('REGISTRO NO PAGAR'!B6="","",'REGISTRO NO PAGAR'!I6) | I6: =IF('REGISTRO NO PAGAR'!B6="","",'REGISTRO NO PAGAR'!J6) | J6: =IF('REGISTRO NO PAGAR'!B6="","",'REGISTRO NO PAGAR'!K6) | K6: =IF('REGISTRO NO PAGAR'!B6="","",'REGISTRO NO PAGAR'!M6) | L6: =IF('REGISTRO NO PAGAR'!B6="","",'REGISTRO NO PAGAR'!N6) | M6: =IF('REGISTRO NO PAGAR'!B6="","",'REGISTRO NO PAGAR'!T6)
A7: =IF('REGISTRO NO PAGAR'!B7="","",'REGISTRO NO PAGAR'!A7) | B7: =IF('REGISTRO NO PAGAR'!B7="","",'REGISTRO NO PAGAR'!B7) | C7: =IF('REGISTRO NO PAGAR'!B7="","",'REGISTRO NO PAGAR'!C7) | D7: =IF('REGISTRO NO PAGAR'!B7="","",'REGISTRO NO PAGAR'!D7) | E7: =IF('REGISTRO NO PAGAR'!B7="","",'REGISTRO NO PAGAR'!E7) | F7: =IF('REGISTRO NO PAGAR'!B7="","",'REGISTRO NO PAGAR'!F7) | G7: =IF('REGISTRO NO PAGAR'!B7="","",'REGISTRO NO PAGAR'!G7) | H7: =IF('REGISTRO NO PAGAR'!B7="","",'REGISTRO NO PAGAR'!I7) | I7: =IF('REGISTRO NO PAGAR'!B7="","",'REGISTRO NO PAGAR'!J7) | J7: =IF('REGISTRO NO PAGAR'!B7="","",'REGISTRO NO PAGAR'!K7) | K7: =IF('REGISTRO NO PAGAR'!B7="","",'REGISTRO NO PAGAR'!M7) | L7: =IF('REGISTRO NO PAGAR'!B7="","",'REGISTRO NO PAGAR'!N7) | M7: =IF('REGISTRO NO PAGAR'!B7="","",'REGISTRO NO PAGAR'!T7)
A8: =IF('REGISTRO NO PAGAR'!B8="","",'REGISTRO NO PAGAR'!A8) | B8: =IF('REGISTRO NO PAGAR'!B8="","",'REGISTRO NO PAGAR'!B8) | C8: =IF('REGISTRO NO PAGAR'!B8="","",'REGISTRO NO PAGAR'!C8) | D8: =IF('REGISTRO NO PAGAR'!B8="","",'REGISTRO NO PAGAR'!D8) | E8: =IF('REGISTRO NO PAGAR'!B8="","",'REGISTRO NO PAGAR'!E8) | F8: =IF('REGISTRO NO PAGAR'!B8="","",'REGISTRO NO PAGAR'!F8) | G8: =IF('REGISTRO NO PAGAR'!B8="","",'REGISTRO NO PAGAR'!G8) | H8: =IF('REGISTRO NO PAGAR'!B8="","",'REGISTRO NO PAGAR'!I8) | I8: =IF('REGISTRO NO PAGAR'!B8="","",'REGISTRO NO PAGAR'!J8) | J8: =IF('REGISTRO NO PAGAR'!B8="","",'REGISTRO NO PAGAR'!K8) | K8: =IF('REGISTRO NO PAGAR'!B8="","",'REGISTRO NO PAGAR'!M8) | L8: =IF('REGISTRO NO PAGAR'!B8="","",'REGISTRO NO PAGAR'!N8) | M8: =IF('REGISTRO NO PAGAR'!B8="","",'REGISTRO NO PAGAR'!T8)
A9: =IF('REGISTRO NO PAGAR'!B9="","",'REGISTRO NO PAGAR'!A9) | B9: =IF('REGISTRO NO PAGAR'!B9="","",'REGISTRO NO PAGAR'!B9) | C9: =IF('REGISTRO NO PAGAR'!B9="","",'REGISTRO NO PAGAR'!C9) | D9: =IF('REGISTRO NO PAGAR'!B9="","",'REGISTRO NO PAGAR'!D9) | E9: =IF('REGISTRO NO PAGAR'!B9="","",'REGISTRO NO PAGAR'!E9) | F9: =IF('REGISTRO NO PAGAR'!B9="","",'REGISTRO NO PAGAR'!F9) | G9: =IF('REGISTRO NO PAGAR'!B9="","",'REGISTRO NO PAGAR'!G9) | H9: =IF('REGISTRO NO PAGAR'!B9="","",'REGISTRO NO PAGAR'!I9) | I9: =IF('REGISTRO NO PAGAR'!B9="","",'REGISTRO NO PAGAR'!J9) | J9: =IF('REGISTRO NO PAGAR'!B9="","",'REGISTRO NO PAGAR'!K9) | K9: =IF('REGISTRO NO PAGAR'!B9="","",'REGISTRO NO PAGAR'!M9) | L9: =IF('REGISTRO NO PAGAR'!B9="","",'REGISTRO NO PAGAR'!N9) | M9: =IF('REGISTRO NO PAGAR'!B9="","",'REGISTRO NO PAGAR'!T9)
A10: =IF('REGISTRO NO PAGAR'!B10="","",'REGISTRO NO PAGAR'!A10) | B10: =IF('REGISTRO NO PAGAR'!B10="","",'REGISTRO NO PAGAR'!B10) | C10: =IF('REGISTRO NO PAGAR'!B10="","",'REGISTRO NO PAGAR'!C10) | D10: =IF('REGISTRO NO PAGAR'!B10="","",'REGISTRO NO PAGAR'!D10) | E10: =IF('REGISTRO NO PAGAR'!B10="","",'REGISTRO NO PAGAR'!E10) | F10: =IF('REGISTRO NO PAGAR'!B10="","",'REGISTRO NO PAGAR'!F10) | G10: =IF('REGISTRO NO PAGAR'!B10="","",'REGISTRO NO PAGAR'!G10) | H10: =IF('REGISTRO NO PAGAR'!B10="","",'REGISTRO NO PAGAR'!I10) | I10: =IF('REGISTRO NO PAGAR'!B10="","",'REGISTRO NO PAGAR'!J10) | J10: =IF('REGISTRO NO PAGAR'!B10="","",'REGISTRO NO PAGAR'!K10) | K10: =IF('REGISTRO NO PAGAR'!B10="","",'REGISTRO NO PAGAR'!M10) | L10: =IF('REGISTRO NO PAGAR'!B10="","",'REGISTRO NO PAGAR'!N10) | M10: =IF('REGISTRO NO PAGAR'!B10="","",'REGISTRO NO PAGAR'!T10)
A11: =IF('REGISTRO NO PAGAR'!B11="","",'REGISTRO NO PAGAR'!A11) | B11: =IF('REGISTRO NO PAGAR'!B11="","",'REGISTRO NO PAGAR'!B11) | C11: =IF('REGISTRO NO PAGAR'!B11="","",'REGISTRO NO PAGAR'!C11) | D11: =IF('REGISTRO NO PAGAR'!B11="","",'REGISTRO NO PAGAR'!D11) | E11: =IF('REGISTRO NO PAGAR'!B11="","",'REGISTRO NO PAGAR'!E11) | F11: =IF('REGISTRO NO PAGAR'!B11="","",'REGISTRO NO PAGAR'!F11) | G11: =IF('REGISTRO NO PAGAR'!B11="","",'REGISTRO NO PAGAR'!G11) | H11: =IF('REGISTRO NO PAGAR'!B11="","",'REGISTRO NO PAGAR'!I11) | I11: =IF('REGISTRO NO PAGAR'!B11="","",'REGISTRO NO PAGAR'!J11) | J11: =IF('REGISTRO NO PAGAR'!B11="","",'REGISTRO NO PAGAR'!K11) | K11: =IF('REGISTRO NO PAGAR'!B11="","",'REGISTRO NO PAGAR'!M11) | L11: =IF('REGISTRO NO PAGAR'!B11="","",'REGISTRO NO PAGAR'!N11) | M11: =IF('REGISTRO NO PAGAR'!B11="","",'REGISTRO NO PAGAR'!T11)
A12: =IF('REGISTRO NO PAGAR'!B12="","",'REGISTRO NO PAGAR'!A12) | B12: =IF('REGISTRO NO PAGAR'!B12="","",'REGISTRO NO PAGAR'!B12) | C12: =IF('REGISTRO NO PAGAR'!B12="","",'REGISTRO NO PAGAR'!C12) | D12: =IF('REGISTRO NO PAGAR'!B12="","",'REGISTRO NO PAGAR'!D12) | E12: =IF('REGISTRO NO PAGAR'!B12="","",'REGISTRO NO PAGAR'!E12) | F12: =IF('REGISTRO NO PAGAR'!B12="","",'REGISTRO NO PAGAR'!F12) | G12: =IF('REGISTRO NO PAGAR'!B12="","",'REGISTRO NO PAGAR'!G12) | H12: =IF('REGISTRO NO PAGAR'!B12="","",'REGISTRO NO PAGAR'!I12) | I12: =IF('REGISTRO NO PAGAR'!B12="","",'REGISTRO NO PAGAR'!J12) | J12: =IF('REGISTRO NO PAGAR'!B12="","",'REGISTRO NO PAGAR'!K12) | K12: =IF('REGISTRO NO PAGAR'!B12="","",'REGISTRO NO PAGAR'!M12) | L12: =IF('REGISTRO NO PAGAR'!B12="","",'REGISTRO NO PAGAR'!N12) | M12: =IF('REGISTRO NO PAGAR'!B12="","",'REGISTRO NO PAGAR'!T12)
A13: =IF('REGISTRO NO PAGAR'!B13="","",'REGISTRO NO PAGAR'!A13) | B13: =IF('REGISTRO NO PAGAR'!B13="","",'REGISTRO NO PAGAR'!B13) | C13: =IF('REGISTRO NO PAGAR'!B13="","",'REGISTRO NO PAGAR'!C13) | D13: =IF('REGISTRO NO PAGAR'!B13="","",'REGISTRO NO PAGAR'!D13) | E13: =IF('REGISTRO NO PAGAR'!B13="","",'REGISTRO NO PAGAR'!E13) | F13: =IF('REGISTRO NO PAGAR'!B13="","",'REGISTRO NO PAGAR'!F13) | G13: =IF('REGISTRO NO PAGAR'!B13="","",'REGISTRO NO PAGAR'!G13) | H13: =IF('REGISTRO NO PAGAR'!B13="","",'REGISTRO NO PAGAR'!I13) | I13: =IF('REGISTRO NO PAGAR'!B13="","",'REGISTRO NO PAGAR'!J13) | J13: =IF('REGISTRO NO PAGAR'!B13="","",'REGISTRO NO PAGAR'!K13) | K13: =IF('REGISTRO NO PAGAR'!B13="","",'REGISTRO NO PAGAR'!M13) | L13: =IF('REGISTRO NO PAGAR'!B13="","",'REGISTRO NO PAGAR'!N13) | M13: =IF('REGISTRO NO PAGAR'!B13="","",'REGISTRO NO PAGAR'!T13)
